Workbook

Sheet BALANCES GENERALES
A1: EMPRESA EL ÉXITO | E1: EMPRESA EL ÉXITO
A2: BALANCE GENERAL | E2: BALANCE GENERAL
A3: AL 31 DE DICIEMBRE 2023 | E3: AL 31 DE DICIEMBRE 2024
A4: Expresado en dólares | E4: Expresado en dólares
A6: ACTIVO | B6: COLUMNA 1 | C6: COLUMNA 2 | E6: ACTIVO | F6: COLUMNA 1 | G6: COLUMNA 2
A7: Corriente | E7: Corriente
A8: Caja | B8: 22300 | E8: Caja | F8: 28500
A9: Banco Americano | B9: 128730 | E9: Banco Americano | F9: 328730
A10: Banco C & P | B10: 438700 | E10: Banco C & P | F10: 686800
A11: Inventario de mercaderías | B11: ='EDO. DE RESULTADOS'!C14 -> 2050300 | E11: Inventario de mercaderías | F11: =-'EDO. DE RESULTADOS'!C21 -> 2248600
A12: Cuentas por cobrar | B12: 2870 | E12: Cuentas por cobrar | F12: 25825
A13: Total activo corriente | C13: =SUM(B8:B12) -> 2642900 | E13: Total activo corriente | G13: =SUM(F8:F12) -> 3318455
A15: No Corriente | E15: No Corriente
A16: Mobiliario y equipo | B16: 48300 | E16: Mobiliario y equipo | F16: 58750
A17: Depreciación acumulada | B17: -19050 | C17: =SUM(B16:B17) -> 29250 | E17: Depreciación acumulada | F17: -29410 | G17: =SUM(F16:F17) -> 29340
A18: Equipo de computación | B18: 35450 | E18: Equipo de computación | F18: 35450
A19: Depreciación acumulada | B19: -7975 | C19: =SUM(B18:B19) -> 27475 | E19: Depreciación acumulada | F19: -16725 | G19: =SUM(F18:F19) -> 18725
A20: Vehículos | B20: 125900 | E20: Vehículos | F20: 150900
A21: Depreciación acumulada | B21: -26000 | C21: =SUM(B20:B21) -> 99900 | E21: Depreciación acumulada | F21: -47860 | G21: =SUM(F20:F21) -> 103040
A22: Total activo no corriente | C22: =SUM(C17:C21) -> 156625 | E22: Total activo no corriente | G22: =SUM(G17:G21) -> 151105
A24: TOTAL DEL ACTIVO | C24: =SUM(C13,C22) -> 2799525 | E24: TOTAL DEL ACTIVO | G24: =SUM(G13,G22) -> 3469560
A26: PASIVO | E26: PASIVO
A27: Corriente | E27: Corriente
A28: Proveedores | B28: 1278565 | E28: Proveedores | F28: 1302602.5
A29: Documentos por pagar | B29: 13150 | E29: Documentos por pagar | F29: 28425
A30: Cuentas por pagar | B30: 20125 | E30: Cuentas por pagar | F30: 35195
A31: Total pasivo corriente | C31: =SUM(B28:B30) -> 1311840 | E31: Total pasivo corriente | G31: =SUM(F28:F30) -> 1366222.5
A33: No corriente | E33: No corriente
A34: Préstamo banco X | B34: 746932 | E34: Préstamo banco M & T | F34: 968410
A35: Total pasivo no corriente | C35: =SUM(B34) -> 746932 | E35: Total pasivo no corriente | G35: =SUM(F34) -> 968410
A37: TOTAL PASIVO | C37: =SUM(C31,C35) -> 2058772 | E37: TOTAL PASIVO | G37: =SUM(G31,G35) -> 2334632.5
A39: CAPITAL | E39: CAPITAL
A40: Capital autorizado | B40: 800000 | E40: Capital autorizado | F40: 800000
A41: Acciones por suscribir | B41: -600000 | E41: Acciones por suscribir | F41: -600000
A42: Utilidad del ejercicio | B42: 540753 | E42: Utilidad del ejercicio | F42: ='EDO. DE RESULTADOS'!D47 -> 934927.5
A43: Total patrimonio | C43: =SUM(B40:B42) -> 740753 | E43: Total patrimonio | G43: =SUM(F40:F42) -> 1134927.5
A45: TOTAL SUMA PASIVO Y CAPITAL | C45: =SUM(C37,C43) -> 2799525 | E45: TOTAL SUMA PASIVO Y CAPITAL | G45: =SUM(G37,G43) -> 3469560
B48: CONFIRMACION | F48: CONFIRMACION
B49: A = P + C | C49: =C37+C43 -> 2799525 | F49: A = P + C | G49: =G37+G43 -> 3469560
B50: A | C50: =C24 -> 2799525 | F50: A | G50: =G24 -> 3469560
...

Sheet EDO. DE RESULTADOS
A1: EMPRESA EL ÉXITO
A2: ESTADO DE RESULTADOS
A3: PERIODO DEL 01 DE ENERO AL 31 DE DICIEMBRE 2024
B6: COLUMNA 1 | C6: COLUMNA 2 | D6: COLUMNA 3 | E6: %
A7: INGRESOS
A8: Total en ventas y servicios | D8: =C9+C10+C11 -> 6147500 | E8: =D8/$D$8 -> 1
A9: Ventas tienda 1 | C9: 3425000 | E9: =C9/$D$8 -> 0.55713705
A10: Ventas tienda 2 | C10: 1987300 | E10: =C10/$D$8 -> 0.32326962
A11: Servicios prestados | C11: 735200 | E11: =C11/$D$8 -> 0.11959333
A13: COSTO DE VENTAS
A14: Inventario inicial de mercadería I | C14: 2050300 | E14: =C14/$D$8 -> 0.33351769
A15: Compras de mercaderías | B15: 4675000 | E15: =B15/$D$8 -> 0.76047174
A16: (+) Fletes sobre compras | B16: 48300 | E16: =B16/$D$8 -> 0.0078568524
A17: Compras brutas | B17: =B15+B16 -> 4723300 | E17: =B17/$D$8 -> 0.76832859
A18: (-) Devoluciones sobre compras | B18: 75800 | E18: =B18/$D$8 -> 0.012330216
A19: Compras netas | C19: =B17-B18 -> 4647500 | E19: =C19/$D$8 -> 0.75599837
A20: Mercadreía disponible | C20: =C14+C19 -> 6697800 | E20: =C20/$D$8 -> 1.0895161
A21: (-) Inventario final de mercadería II | C21: -2248600 | E21: =C21/$D$8 -> -0.36577471
A22: Costo de ventas | D22: =C20+C21 -> 4449200 | E22: =D22/$D$8 -> 0.72374136
A23: Utilidad bruta | D23: =D8-D22 -> 1698300 | E23: =D23/$D$8 -> 0.27625864
A25: GASTOS DE OPERACIÓN
A26: Gastos administrativos
A27: Gastos generales | C27: 4500 | E27: =C27/$D$8 -> 0.00073200488
A28: Alquileres | C28: =3500*12 -> 42000 | E28: =C28/$D$8 -> 0.0068320455
A29: Papelería y útiles | C29: =475*12 -> 5700 | E29: =C29/$D$8 -> 0.00092720618
A30: Servicio telefónico é internet | C30: =425*12 -> 5100 | E30: =C30/$D$8 -> 0.00082960553
A31: Sueldos y salarios | C31: =4000*6*12 -> 288000 | E31: =C31/$D$8 -> 0.046848312
A32: Bonificación incentivo | C32: =250*6*12 -> 18000 | E32: =C32/$D$8 -> 0.0029280195
A33: Bono 14 | C33: =4000*6 -> 24000 | E33: =C33/$D$8 -> 0.003904026
A34: Aguinaldo | C34: =4000*6 -> 24000 | E34: =C34/$D$8 -> 0.003904026
A35: Depreciación mobiliario y equipo | C35: 10360 | E35: =C35/$D$8 -> 0.0016852379
A36: Depreciación equipo de computación | C36: 8750 | E36: =C36/$D$8 -> 0.0014233428
A37: Depreciación vehículos | C37: 21860 | E37: =C37/$D$8 -> 0.003555917
D38: =SUM(C27:C37) -> 452270 | E38: =D38/$D$8 -> 0.073569744
A39: Gastos y productos financieros
A40: Intereses sobre préstamos | C40: 2585 | E40: =C40/$D$8 -> 0.00042049614
A41: Intereses devengados cuentas bancarias | C41: -3125
D42: =SUM(C40:C41) -> -540 | E42: =D42/$D$8 -> -8.7840586e-05
E43: =D43/$D$8 -> 0
A44: Total gastos de operación | D44: =D38+D42+D43 -> 451730 | E44: =D44/$D$8 -> 0.073481903
...

Sheet CLASIFICACIÓN CUENTAS
A1: CUENTAS | B1: 2023 | C1: 2024 | D1: VARIACIONES | E1: CAMBIOS | G1: INVERSIÓN | H1: FINANCIAMIENTO | I1: EFECTIVO | J1: ANALISIS DE CAMBIOS
E2: ACTIVO | F2: PASIVO
A3: ='BALANCES GENERALES'!E6 -> ACTIVO
A4: ='BALANCES GENERALES'!E7 -> Corriente
A5: efectivo y equivalentes de efectivo | B5: =SUM('BALANCES GENERALES'!B8:B10) -> 589730 | C5: =SUM('BALANCES GENERALES'!F8:F10) -> 1044030 | D5: =C5-B5 -> 454300 | I5: =D5 -> 454300 | J5: Ha aumentado el dinero en estas cuentas que reflejan efectivo o dinero literalmente
I6: =D6 -> 0
I7: =D7 -> 0
A8: ='BALANCES GENERALES'!E11 -> Inventario de mercaderías | B8: ='BALANCES GENERALES'!B11 -> 2050300 | C8: ='BALANCES GENERALES'!F11 -> 2248600 | D8: =C8-B8 -> 198300 | E8: =-D8 -> -198300 | J8: Se ha comprado mercaderia por lo que el dinero disminuye
A9: ='BALANCES GENERALES'!E12 -> Cuentas por cobrar | B9: ='BALANCES GENERALES'!B12 -> 2870 | C9: ='BALANCES GENERALES'!F12 -> 25825 | D9: =C9-B9 -> 22955 | E9: =-D9 -> -22955 | J9: Se ha vendido al credito o se ha brindado una venta que es exigible
A10: ='BALANCES GENERALES'!E15 -> No Corriente
A11: ='BALANCES GENERALES'!E16 -> Mobiliario y equipo | B11: ='BALANCES GENERALES'!B16 -> 48300 | C11: ='BALANCES GENERALES'!F16 -> 58750 | D11: =C11-B11 -> 10450 | G11: =-D11 -> -10450
A12: Depreciacion mobiliario y equipo | B12: =ABS('BALANCES GENERALES'!B17) -> 19050 | C12: =ABS('BALANCES GENERALES'!F17) -> 29410 | D12: =C12-B12 -> 10360 | F12: =D12 -> 10360 | J12: no cuenta como movimiento de dinero
A13: ='BALANCES GENERALES'!E18 -> Equipo de computación | B13: ='BALANCES GENERALES'!B18 -> 35450 | C13: ='BALANCES GENERALES'!F18 -> 35450 | D13: =C13-B13 -> 0
A14: Depreciacion equipo de computacion | B14: =ABS('BALANCES GENERALES'!B19) -> 7975 | C14: =ABS('BALANCES GENERALES'!F19) -> 16725 | D14: =C14-B14 -> 8750 | F14: =D14 -> 8750 | J14: =J12 -> no cuenta como movimiento de dinero
A15: ='BALANCES GENERALES'!E20 -> Vehículos | B15: ='BALANCES GENERALES'!B20 -> 125900 | C15: ='BALANCES GENERALES'!F20 -> 150900 | D15: =C15-B15 -> 25000 | G15: =-D15 -> -25000
A16: Depreciacion vehiculos | B16: =ABS('BALANCES GENERALES'!B21) -> 26000 | C16: =ABS('BALANCES GENERALES'!F21) -> 47860 | D16: =C16-B16 -> 21860 | F16: =D16 -> 21860 | J16: =J14 -> no cuenta como movimiento de dinero
A17: ='BALANCES GENERALES'!E26 -> PASIVO
A18: ='BALANCES GENERALES'!E27 -> Corriente
A19: ='BALANCES GENERALES'!E28 -> Proveedores | B19: ='BALANCES GENERALES'!B28 -> 1278565 | C19: ='BALANCES GENERALES'!F28 -> 1302602.5 | D19: =C19-B19 -> 24037.5 | F19: =D19 -> 24037.5
A20: ='BALANCES GENERALES'!E29 -> Documentos por pagar | B20: ='BALANCES GENERALES'!B29 -> 13150 | C20: ='BALANCES GENERALES'!F29 -> 28425 | D20: =C20-B20 -> 15275 | F20: =D20 -> 15275
A21: ='BALANCES GENERALES'!E30 -> Cuentas por pagar | B21: ='BALANCES GENERALES'!B30 -> 20125 | C21: ='BALANCES GENERALES'!F30 -> 35195 | D21: =C21-B21 -> 15070 | F21: =D21 -> 15070
A22: ='BALANCES GENERALES'!E33 -> No corriente
A23: ='BALANCES GENERALES'!E34 -> Préstamo banco M & T | B23: 0 | C23: ='BALANCES GENERALES'!F34 -> 968410 | D23: =C23-B23 -> 968410 | H23: =D23 -> 968410
A24: ='BALANCES GENERALES'!A34 -> Préstamo banco X | B24: ='BALANCES GENERALES'!B34 -> 746932 | C24: 0 | D24: =C24-B24 -> -746932 | H24: =D24 -> -746932
A25: ='BALANCES GENERALES'!A39 -> CAPITAL
A26: ='BALANCES GENERALES'!E40 -> Capital autorizado | B26: ='BALANCES GENERALES'!B40 -> 800000 | C26: ='BALANCES GENERALES'!F40 -> 800000 | D26: =C26-B26 -> 0
A27: ='BALANCES GENERALES'!E41 -> Acciones por suscribir | B27: ='BALANCES GENERALES'!B41 -> -600000 | C27: ='BALANCES GENERALES'!F41 -> -600000 | D27: =C27-B27 -> 0
A28: ='BALANCES GENERALES'!E42 -> Utilidad del ejercicio | B28: ='BALANCES GENERALES'!B42 -> 540753 | C28: ='BALANCES GENERALES'!F42 -> 934927.5 | D28: =C28-B28 -> 394174.5 | F28: =D28 -> 394174.5 | J28: =J16 -> no cuenta como movimiento de dinero
A30: TOTAL DEL PASIVO Y CAPITAL

Sheet flujo de efectivo
A1: EMPRESA LA ESQUINA 20
A2: ESTADO DE FLUJO DE EFECTIVO
A3: AL 31 DE DICIEMBRE 2024
A4: Expresado en quetzales
B6: COLUMNA 1 | C6: COLUMNA 2
A7: VARIACIONES DE FLUJO DE EFECTIVO
A8: Utilidad del ejercicio | C8: ='CLASIFICACIÓN CUENTAS'!C28 -> 934927.5
A9: Gastos por depreciacion de mobiliario y equipo | C9: ='CLASIFICACIÓN CUENTAS'!F12 -> 10360
A10: Gastos por depreciacion de equipo de computacion | C10: ='CLASIFICACIÓN CUENTAS'!F14 -> 8750
A11: Gasto por depreciacion de vehiculos | C11: ='CLASIFICACIÓN CUENTAS'!F16 -> 21860
A12: utilidad ajustada | C12: =SUM(C8:C11) -> 975897.5
A13: FLUJO DE EFECTIVO POR ACTIVIDADES DE OPERACIÓN
A14: Aumento por mercaderias | B14: ='CLASIFICACIÓN CUENTAS'!E8 -> -198300
A15: Aumento de cuentas por cobrar | B15: ='CLASIFICACIÓN CUENTAS'!E9 -> -22955
A16: Aumento por proveedores | B16: ='CLASIFICACIÓN CUENTAS'!F19 -> 24037.5
A17: Aumento por documentos por pagar | B17: ='CLASIFICACIÓN CUENTAS'!F20 -> 15275
A18: Aumento por cuentas por pagar | B18: ='CLASIFICACIÓN CUENTAS'!F21 -> 15070
A19: efectivo neto por actividades de operación | C19: =SUM(B14:B18) -> -166872.5
A20: FLUJO DE EFECTIVO POR ACTIVIDADES DE INVERSIÓN
A21: Aumento por mobiliario y equipo | B21: ='CLASIFICACIÓN CUENTAS'!G11 -> -10450
A22: Aumento por vehiculos | B22: ='CLASIFICACIÓN CUENTAS'!G15 -> -25000
A23: efectivo neto por actividades de inversión | C23: =SUM(B21:B22) -> -35450
A24: FLUJO DE EFECTIVO POR ACTIVIDADES DE FINANCIAMIENTO
A25: Aumento por prestamo de banco M & K | B25: ='CLASIFICACIÓN CUENTAS'!H23 -> 968410
A26: Disminucion por prestamo banco X | B26: ='CLASIFICACIÓN CUENTAS'!D24 -> -746932
A27: efectivo neto por actividades de financiamiento | C27: =SUM(B25:B26) -> 221478
A28: FLUJO DE EFECTIVO NETO Y EQUIVALENTES DE EFECTIVO | C28: =SUM(C12:C27) -> 995053
A29: ='CLASIFICACIÓN CUENTAS'!A5 -> efectivo y equivalentes de efectivo | C29: ='CLASIFICACIÓN CUENTAS'!B5 -> 589730
A30: ='CLASIFICACIÓN CUENTAS'!A6 -> 0 | C30: ='CLASIFICACIÓN CUENTAS'!B6 -> 0
A31: ='CLASIFICACIÓN CUENTAS'!A7 -> 0 | C31: ='CLASIFICACIÓN CUENTAS'!B7 -> 0
A32: efectivo y equivalentes de efectivo al 31 de diciembre 2024 | C32: =SUM(C28:C31) -> 1584783
